<?xml version="1.0"?>
<robot name="urdfbot">

    <link name="mani_link1">
        <visual>
            <geometry>
                <mesh filename="package://urdfbot_description/meshes/visual/mani_1.stl" />
            </geometry>
        </visual>
        <collision>
            <geometry>
                <mesh filename="package://urdfbot_description/meshes/collision/mani_1.stl" />
            </geometry>
        </collision>
    </link>


    <link name="mani_link2">
        <visual>
            <geometry>
                <mesh filename="package://urdfbot_description/meshes/visual/mani_2.stl" />
            </geometry>
        </visual>
        <collision>
            <geometry>
                <mesh filename="package://urdfbot_description/meshes/collision/mani_2.stl" />
            </geometry>
        </collision>
    </link>

    <joint name="mani_joint1" type="revolute">
        <safety_controller k_position="100.0" k_velocity="40.0" soft_lower_limit="-2.8973" soft_upper_limit="2.8973" />
        <origin rpy="0 0 0" xyz="0 0 62" />
        <parent link="mani_link1" />
        <child link="mani_link2" />
        <axis xyz="0 0 1" />
        <limit effort="87" lower="-2.9671" upper="2.9671" velocity="2.3925" />
    </joint>

    <link name="mani_link3">
        <visual>
            <geometry>
                <mesh filename="package://urdfbot_description/meshes/visual/mani_3.stl" />
            </geometry>
        </visual>
        <collision>
            <geometry>
                <mesh filename="package://urdfbot_description/meshes/collision/mani_3.stl" />
            </geometry>
        </collision>
    </link>

    <joint name="mani_joint2" type="revolute">
        <safety_controller k_position="100.0" k_velocity="40.0" soft_lower_limit="-2.8973" soft_upper_limit="2.8973" />
        <origin rpy="0 -1.57075 0" xyz="22.85 0 47" />
        <parent link="mani_link2" />
        <child link="mani_link3" />
        <axis xyz="0 0 1" />
        <limit effort="87" lower="-2.9671" upper="2.9671" velocity="2.3925" />
    </joint>

    <link name="mani_link4">
        <visual>
            <geometry>
                <mesh filename="package://urdfbot_description/meshes/visual/mani_4.stl" />
            </geometry>
        </visual>
        <collision>
            <geometry>
                <mesh filename="package://urdfbot_description/meshes/collision/mani_4.stl" />
            </geometry>
        </collision>
    </link>

    <joint name="mani_joint3" type="revolute">
        <safety_controller k_position="100.0" k_velocity="40.0" soft_lower_limit="-2.8973" soft_upper_limit="2.8973" />
        <origin rpy="0 0 1.57075" xyz="319.5 0 45.5" />
        <parent link="mani_link3" />
        <child link="mani_link4" />
        <axis xyz="0 0 1" />
        <limit effort="87" lower="-2.9671" upper="2.9671" velocity="2.3925" />
    </joint>

    <link name="mani_link5">
        <visual>
            <geometry>
                <mesh filename="package://urdfbot_description/meshes/visual/mani_5.stl" />
            </geometry>
        </visual>
        <collision>
            <geometry>
                <mesh filename="package://urdfbot_description/meshes/collision/mani_5.stl" />
            </geometry>
        </collision>
    </link>

    <joint name="mani_joint4" type="revolute">
        <safety_controller k_position="100.0" k_velocity="40.0" soft_lower_limit="-2.8973" soft_upper_limit="2.8973" />
        <origin rpy="0 -1.57075 1.57075" xyz="66.0 -64 -22" />
        <parent link="mani_link4" />
        <child link="mani_link5" />
        <axis xyz="0 0 1" />
        <limit effort="87" lower="-2.9671" upper="2.9671" velocity="2.3925" />
    </joint>

    <link name="mani_link6">
        <visual>
            <geometry>
                <mesh filename="package://urdfbot_description/meshes/visual/mani_6.stl" />
            </geometry>
        </visual>
        <collision>
            <geometry>
                <mesh filename="package://urdfbot_description/meshes/collision/mani_6.stl" />
            </geometry>
        </collision>
    </link>

    <joint name="mani_joint5" type="revolute">
        <safety_controller k_position="100.0" k_velocity="40.0" soft_lower_limit="-2.8973" soft_upper_limit="2.8973" />
        <origin rpy="0 0 0" xyz="0 0 248.75" />
        <parent link="mani_link5" />
        <child link="mani_link6" />
        <axis xyz="0 0 1" />
        <limit effort="87" lower="-2.9671" upper="2.9671" velocity="2.3925" />
    </joint>

    <link name="mani_link7">
        <visual>
            <geometry>
                <mesh filename="package://urdfbot_description/meshes/visual/mani_7.stl" />
            </geometry>
        </visual>
        <collision>
            <geometry>
                <mesh filename="package://urdfbot_description/meshes/collision/mani_7.stl" />
            </geometry>
        </collision>
    </link>

    <joint name="mani_joint6" type="revolute">
        <safety_controller k_position="100.0" k_velocity="40.0" soft_lower_limit="-2.8973" soft_upper_limit="2.8973" />
        <origin rpy="0 0 0" xyz="0 0 56.5" />
        <parent link="mani_link6" />
        <child link="mani_link7" />
        <axis xyz="0 0 1" />
        <limit effort="87" lower="-2.9671" upper="2.9671" velocity="2.3925" />
    </joint>




</robot>